Workbook

Sheet Dashboard
B2: CURVA DE JUROS DI — ESTRUTURA A TERMO
B3: Interpolação Flat Forward 252 | Dados: ANBIMA (ETTJ Prefixada)
B5: DATA REFERÊNCIA | E5: TAXA CURTA (21 DU) | H5: TAXA LONGA (2520 DU) | K5: SPREAD / FORMATO
B6: 25/03/2026 | E6: 14.64% a.a. | H6: 14.00% a.a. | K6: -64 bps | Invertida
K7: Taxa curta > Taxa longa
B9: DU | C9: Spot 25/03/2026 (hoje) | D9: Spot 09/02/2026 (30 DU atras) | E9: Forward Mes a Mes
B10: 42 | C10: 14.55 | D10: 14.74 | E10: =Aux!E3*100 -> 14.460071
B11: 84 | C11: 14.42 | D11: 14.4 | E11: =Aux!E5*100 -> 14.240189
B12: 126 | C12: 14.31 | D12: 14.07 | E12: =Aux!E7*100 -> 14.090317
B13: 168 | C13: 14.219988 | D13: 13.702302 | E13: =Aux!E9*100 -> 13.950378
B14: 210 | C14: 14.157993 | D14: 13.427847 | E14: =Aux!E11*100 -> 13.870336
B15: 252 | C15: 14.11 | D15: 13.2 | E15: =Aux!E13*100 -> 13.870336
B16: 294 | C16: 14.049979 | D16: 13.019809 | E16: =Aux!E15*100 -> 13.690515
B17: 336 | C17: 14.004984 | D17: 12.884854 | E17: =Aux!E17*100 -> 13.690515
B18: 378 | C18: 13.97 | D18: 12.78 | E18: =Aux!E19*100 -> 13.690515
B19: 420 | C19: 13.929989 | D19: 12.719976 | E19: =Aux!E21*100 -> 13.570526
B20: 462 | C20: 13.897264 | D20: 12.670889 | E20: =Aux!E23*100 -> 13.570526
B21: 504 | C21: 13.87 | D21: 12.63 | E21: =Aux!E25*100 -> 13.570526
B22: 546 | C22: 13.87 | D22: 12.637692 | E22: =Aux!E27*100 -> 13.87
B23: 588 | C23: 13.87 | D23: 12.644285 | E23: =Aux!E29*100 -> 13.87
B24: 630 | C24: 13.87 | D24: 12.65 | E24: =Aux!E31*100 -> 13.87
B25: 672 | C25: 13.881249 | D25: 12.679993 | E25: =Aux!E33*100 -> 14.050119
B26: 714 | C26: 13.891176 | D26: 12.706465 | E26: =Aux!E35*100 -> 14.050119
B27: 756 | C27: 13.9 | D27: 12.73 | E27: =Aux!E37*100 -> 14.050119
B28: 798 | C28: 13.911052 | D28: 12.770514 | E28: =Aux!E39*100 -> 14.110166
B29: 840 | C29: 13.920999 | D29: 12.806989 | E29: =Aux!E41*100 -> 14.110166
B30: 882 | C30: 13.93 | D30: 12.84 | E30: =Aux!E43*100 -> 14.110166
B31: 924 | C31: 13.937272 | D31: 12.879988 | E31: =Aux!E45*100 -> 14.090098
B32: CONSULTA DE TAXA INTERPOLADA
B33: 1008 | C33: 13.95 | D33: 12.95 | E33: =Aux!E49*100 -> 14.090098
B34: Selecione o vencimento: | C34: 14.26 | D34: Mar/2027 (252 DU) | F34: << clique aqui
B35: 1092 | C35: 13.970768 | D35: 13.0123 | E35: =Aux!E53*100 -> 14.220285
B36: Taxa interpolada: | C36: 14.24 | D36: =VLOOKUP(D34,Aux!A:C,3,FALSE()) -> 0.1411 | E36: =Aux!E28*100 -> 13.87 | F36: Taxa 30d atrás: | H36: =VLOOKUP(D34,Aux!A:D,4,FALSE()) -> 0.132
B37: Dias úteis: | C37: 14.23 | D37: =VLOOKUP(D34,Aux!A:B,2,FALSE()) -> 252 | E37: =Aux!E29*100 -> 13.87 | F37: Variação (bps): | H37: =(D36-H36)*10000 -> 91
B38: 1218 | C38: 14.000689 | D38: 13.102061 | E38: =Aux!E59*100 -> 14.280356
B40: PRECIFICAÇÃO DE TÍTULO PREFIXADO (LTN)
B42: Título: | D42: LTN Set/2027 | F42: << clique aqui | G42: DU até vencimento: | I42: =VLOOKUP(D42,Aux!F:G,2,FALSE()) -> 378
B43: Valor de Face: | D43: 1000 | G43: Taxa da curva: | I43: =INDEX(Aux!C:C,MATCH(I42,Aux!B:B,0)) -> 0.1397
B45: PREÇO UNITÁRIO (PU) | E45: DURATION (ANOS) | H45: DV01 (R$)
B46: =D43/((1+I43)^(I42/252)) -> 821.89091 | E46: =I42/252 -> 1.5 | H46: =(D43/((1+I43-0.0001)^(I42/252)) - D43/((1+I43+0.0001)^(I42/252)))/2 -> 0.10817201
...

Sheet Aux
A1: Vencimento | B1: Prazo (DU) | C1: Spot 25/03/2026 | D1: Spot 09/02/2026 | E1: Forward Mes a Mes | F1: LTN | G1: Prazo (DU)
A2: Abr/2026 (21 DU) | B2: 21 | C2: 0.1464 | D2: 0.1485 | E2: 0.1464 | F2: LTN Mai/2026 | G2: 42
A3: Mai/2026 (42 DU) | B3: 42 | C3: 0.1455 | D3: 0.1474 | E3: 0.14460071 | F3: LTN Jun/2026 | G3: 63
A4: Jun/2026 (63 DU) | B4: 63 | C4: 0.1448 | D4: 0.146 | E4: 0.14340128 | F4: LTN Jul/2026 | G4: 84
A5: Jul/2026 (84 DU) | B5: 84 | C5: 0.1442 | D5: 0.144 | E5: 0.14240189 | F5: LTN Ago/2026 | G5: 105
A6: Ago/2026 (105 DU) | B6: 105 | C6: 0.14353987 | D6: 0.14201886 | E6: 0.14090317 | F6: LTN Set/2026 | G6: 126
A7: Set/2026 (126 DU) | B7: 126 | C7: 0.1431 | D7: 0.1407 | E7: 0.14090317 | F7: LTN Out/2026 | G7: 147
A8: Out/2026 (147 DU) | B8: 147 | C8: 0.14258556 | D8: 0.13859742 | E8: 0.13950378 | F8: LTN Nov/2026 | G8: 168
A9: Nov/2026 (168 DU) | B9: 168 | C9: 0.14219988 | D9: 0.13702302 | E9: 0.13950378 | F9: LTN Dez/2026 | G9: 189
A10: Dez/2026 (189 DU) | B10: 189 | C10: 0.1419 | D10: 0.1358 | E10: 0.13950378 | F10: LTN Jan/2027 | G10: 210
A11: Jan/2027 (210 DU) | B11: 210 | C11: 0.14157993 | D11: 0.13427847 | E11: 0.13870336 | F11: LTN Fev/2027 | G11: 231
A12: Fev/2027 (231 DU) | B12: 231 | C12: 0.14131813 | D12: 0.1330351 | E12: 0.13870336 | F12: LTN Mar/2027 | G12: 252
A13: Mar/2027 (252 DU) | B13: 252 | C13: 0.1411 | D13: 0.132 | E13: 0.13870336 | F13: LTN Abr/2027 | G13: 273
... A58: Dez/2030 (1197 DU) | B58: 1197 | C58: 0.13995788 | D58: 0.13087359 | E58: 0.14280356 | F58: LTN Jan/2031 | G58: 1218
A59: Jan/2031 (1218 DU) | B59: 1218 | C59: 0.14000689 | D59: 0.13102061 | E59: 0.14280356

Sheet Vértices
B2: TABELA DE VÉRTICES — ETTJ PREFIXADA
B3: Data de referência: 25/03/2026 | Curva: PRE | Fonte: ANBIMA | H3: O que é a coluna 'Spot 09/02/2026'? Ela mostra a taxa de juros para cada prazo conforme publicada pela ANBIMA há 30 dias úteis (em 09/02/2026). Não é uma taxa nova, é a mesma curva de hoje, só que fotografada no passado. Compare com a coluna 'Spot hoje' para ver se os juros subiram ou caíram no período.
B5: Prazo (DU) | C5: Spot 25/03/2026 (% a.a.) | D5: Forward Mes a Mes (% a.a.) | E5: Fator de Desconto | F5: Tipo | G5: Spot 09/02/2026 (% a.a.)
B6: 21 | C6: 0.1464 | D6: 0.1464 | E6: 0.98867902 | F6: Original | G6: 0.1485
B7: 42 | C7: 0.1455 | D7: 0.14460071 | E7: 0.97761416 | F7: Original | G7: 0.1474
B8: 63 | C8: 0.1448 | D8: 0.14340128 | E8: 0.9667576 | F8: Original | G8: 0.146
B9: 84 | C9: 0.1442 | D9: 0.14240189 | E9: 0.95609127 | F9: Original | G9: 0.144
B10: 105 | C10: 0.14353987 | D10: 0.14090317 | E10: 0.94564607 | F10: Interpolado | G10: 0.14201886
B11: 126 | C11: 0.1431 | D11: 0.14090317 | E11: 0.93531497 | F11: Original | G11: 0.1407
B12: 147 | C12: 0.14258556 | D12: 0.13950378 | E12: 0.92519137 | F12: Interpolado | G12: 0.13859742
B13: 168 | C13: 0.14219988 | D13: 0.13950378 | E13: 0.91517734 | F13: Interpolado | G13: 0.13702302
B14: 189 | C14: 0.1419 | D14: 0.13950378 | E14: 0.9052717 | F14: Original | G14: 0.1358
B15: 210 | C15: 0.14157993 | D15: 0.13870336 | E15: 0.89552572 | F15: Interpolado | G15: 0.13427847
B16: 231 | C16: 0.14131813 | D16: 0.13870336 | E16: 0.88588465 | F16: Interpolado | G16: 0.1330351
B17: 252 | C17: 0.1411 | D17: 0.13870336 | E17: 0.87634738 | F17: Original | G17: 0.132
... B63: 1218 | C63: 0.14000689 | D63: 0.14280356 | E63: 0.53081991 | F63: Interpolado | G63: 0.13102061

Sheet Movimentos
B2: ANÁLISE DE MOVIMENTOS — VARIAÇÃO EM BASIS POINTS
B3: Comparação: 25/03/2026 vs. 09/02/2026 (30 dias úteis)
B5: Vértice (DU) | C5: Taxa Hoje (%) | D5: Taxa 30d (%) | E5: Variação (bps) | F5: Direção | H5: SHIFT PARALELO (MÉDIA)
B6: 21 | C6: 0.1464 | D6: 0.1485 | E6: =(C6-D6)*10000 -> -21 | F6: - Fechou | H6: =AVERAGE(E6:E14) -> 54.666667
B7: 42 | C7: 0.1455 | D7: 0.1474 | E7: =(C7-D7)*10000 -> -19 | F7: - Fechou | H7: bps (média todos vértices)
B8: 63 | C8: 0.1448 | D8: 0.146 | E8: =(C8-D8)*10000 -> -12 | F8: - Fechou | H8: TIPO DE MOVIMENTO
B9: 126 | C9: 0.1431 | D9: 0.1407 | E9: =(C9-D9)*10000 -> 24 | F9: + Abriu | H9: =IF(ABS(E14-E6)>10,IF(E14>E6,"Steepening","Flattening"),"Paralelo") -> Steepening
B10: 252 | C10: 0.1411 | D10: 0.132 | E10: =(C10-D10)*10000 -> 91 | F10: + Abriu | H10: =CONCATENATE("Longo: ",TEXT(E14,"+0;-0")," bps | Curto: ",TEXT(E6,"+0;-0")," bps") -> Longo: +88 bps | Curto: -21 bps
B11: 504 | C11: 0.1387 | D11: 0.1263 | E11: =(C11-D11)*10000 -> 124 | F11: + Abriu
B12: 756 | C12: 0.139 | D12: 0.1273 | E12: =(C12-D12)*10000 -> 117 | F12: + Abriu
B13: 1008 | C13: 0.1395 | D13: 0.1295 | E13: =(C13-D13)*10000 -> 100 | F13: + Abriu
B14: 1260 | C14: 0.1401 | D14: 0.1313 | E14: =(C14-D14)*10000 -> 88 | F14: + Abriu | H14: O que é a coluna 'Spot 09/02/2026'? Ela mostra a taxa de juros para cada prazo conforme publicada pela ANBIMA há 30 dias úteis (em 09/02/2026). Não é uma taxa nova, é a mesma curva de hoje, só que fotografada no passado. Compare com a coluna 'Spot hoje' para ver se os juros subiram ou caíram no período.
B16: MÉDIA DA VARIAÇÃO | E16: =AVERAGE(E6:E14) -> 54.666667
